tools/gcc/git(41):ERROR:105: Unable to locate a modulefile for 'tools/gcc/git/2.8.2'
              total        used        free      shared  buff/cache   available
Mem:         128677       10099       50625         695       67952      117271
Swap:         16383         472       15911
/opt/site/sge/default/spool/node746/job_scripts/2485343: line 14: nvidia-smi: command not found
2021-06-03 11:13:15.936282: I tensorflow/stream_executor/platform/default/dso_loader.cc:49] Successfully opened dynamic library libcudart.so.10.1
Traceback (most recent call last):
  File "train_step2.py", line 13, in <module>
    from model.step_2 import train_this
  File "/mnt/jw01-aruk-home01/projects/ra_challenge/hestia/Hestia_imeche_vision_challenge/NN_recognition_train/model/step_2.py", line 8, in <module>
    from dataset.secondary_generator import retrieve_tf_dataset_secondary, secondary_generator
  File "/mnt/jw01-aruk-home01/projects/ra_challenge/hestia/Hestia_imeche_vision_challenge/NN_recognition_train/dataset/secondary_generator.py", line 32, in <module>
    model_step_1 = k.models.load_model(f"weights/{model_to_use}", custom_objects = {"custom_mse": custom_mse})
  File "/mnt/jw01-aruk-home01/projects/psa_functional_genomics/differential_HiC_analyser/conda_env/lib/python3.8/site-packages/tensorflow/python/keras/saving/save.py", line 211, in load_model
    loader_impl.parse_saved_model(filepath)
  File "/mnt/jw01-aruk-home01/projects/psa_functional_genomics/differential_HiC_analyser/conda_env/lib/python3.8/site-packages/tensorflow/python/saved_model/loader_impl.py", line 111, in parse_saved_model
    raise IOError("SavedModel file does not exist at: %s/{%s|%s}" %
OSError: SavedModel file does not exist at: weights/step1_without_trainable.tf/{saved_model.pbtxt|saved_model.pb}
